<?xml version="1.0" encoding="UTF-8"?>
<!-- Generated by org.testng.reporters.JUnitReportReporter -->
<testsuite hostname="PPTLAP104" failures="1" tests="2" name="testngOdoo.Scenario1" time="91.413" errors="0" timestamp="2025-03-05T15:57:20 IST" skipped="0">
  <testcase classname="testngOdoo.Scenario1" name="createSalesOrder" time="23.779"/>
  <testcase classname="testngOdoo.Scenario1" name="duplicateTabAndCheckPO" time="67.634">
    <failure message="PO quantity does not match with the Calculated value. expected [34.0] but found [22.0]" type="java.lang.AssertionError">
      <![CDATA[java.lang.AssertionError: PO quantity does not match with the Calculated value. expected [34.0] but found [22.0]
at org.testng.Assert.fail(Assert.java:111)
at org.testng.Assert.failNotEquals(Assert.java:1578)
at org.testng.Assert.assertEquals(Assert.java:728)
at testngOdoo.Scenario1.duplicateTabAndCheckPO(Scenario1.java:300)
at java.base/jdk.internal.reflect.DirectMethodHandleAccessor.invoke(DirectMethodHandleAccessor.java:103)
at java.base/java.lang.reflect.Method.invoke(Method.java:580)
at org.testng.internal.invokers.MethodInvocationHelper.invokeMethod(MethodInvocationHelper.java:141)
at org.testng.internal.invokers.TestInvoker.invokeMethod(TestInvoker.java:686)
at org.testng.internal.invokers.TestInvoker.invokeTestMethod(TestInvoker.java:230)
at org.testng.internal.invokers.MethodRunner.runInSequence(MethodRunner.java:63)
at org.testng.internal.invokers.TestInvoker$MethodInvocationAgent.invoke(TestInvoker.java:992)
at org.testng.internal.invokers.TestInvoker.invokeTestMethods(TestInvoker.java:203)
at org.testng.internal.invokers.TestMethodWorker.invokeTestMethods(TestMethodWorker.java:154)
at org.testng.internal.invokers.TestMethodWorker.run(TestMethodWorker.java:134)
at java.base/java.util.ArrayList.forEach(ArrayList.java:1596)
at org.testng.TestRunner.privateRun(TestRunner.java:739)
at org.testng.TestRunner.run(TestRunner.java:614)
at org.testng.SuiteRunner.runTest(SuiteRunner.java:421)
at org.testng.SuiteRunner.runSequentially(SuiteRunner.java:413)
at org.testng.SuiteRunner.privateRun(SuiteRunner.java:373)
at org.testng.SuiteRunner.run(SuiteRunner.java:312)
at org.testng.SuiteRunnerWorker.runSuite(SuiteRunnerWorker.java:52)
at org.testng.SuiteRunnerWorker.run(SuiteRunnerWorker.java:95)
at org.testng.TestNG.runSuitesSequentially(TestNG.java:1274)
at org.testng.TestNG.runSuitesLocally(TestNG.java:1208)
at org.testng.TestNG.runSuites(TestNG.java:1112)
at org.testng.TestNG.run(TestNG.java:1079)
at org.testng.remote.AbstractRemoteTestNG.run(AbstractRemoteTestNG.java:115)
at org.testng.remote.RemoteTestNG.initAndRun(RemoteTestNG.java:293)
at org.testng.remote.RemoteTestNG.main(RemoteTestNG.java:91)
]]>
    </failure>
  </testcase> <!-- duplicateTabAndCheckPO -->
</testsuite> <!-- testngOdoo.Scenario1 -->
